<?xml version="1.0" ?>
<robot name="hokuyo_laser_robot" xmlns:xacro="http://www.ros.org/wiki/xacro">

<xacro:include filename="$(find hokuyo_laser_robot_description)/urdf/materials.xacro" />
<xacro:include filename="$(find hokuyo_laser_robot_description)/urdf/hokuyo_laser_robot.trans" />
<xacro:include filename="$(find hokuyo_laser_robot_description)/urdf/hokuyo_laser_robot.gazebo" />
<xacro:property name="camera_link" value="0.05" />


<link name="base_link">
  <inertial>
    <origin rpy="0 0 0" xyz="9.043189420795964e-17 -1.0687405679122504e-16 0.04642781600587486"/>
    <mass value="0.0821424569482983"/>
    <inertia ixx="0.000156" ixy="0.0" ixz="0.0" iyy="0.000168" iyz="0.0" izz="0.00015"/>
  </inertial>
  <visual>
    <origin rpy="0 0 0" xyz="0 0 0.0"/>
    <geometry>
      <mesh filename="package://hokuyo_laser_robot_description/meshes/base_link.stl" scale="0.001 0.001 0.001"/>
    </geometry>
    <material name="grey"/>
  </visual>
  <collision>
     <origin rpy="0 0 0" xyz="0 0 0.0"/>
     <geometry>
      <mesh filename="package://hokuyo_laser_robot_description/meshes/base_link.stl" scale="0.001 0.001 0.001"/>
     </geometry>
    
  </collision>

</link>

<link name="wheelv1_1">
  <inertial>
    <origin rpy="0 0 0" xyz="0.0 0.0 0.0"/>
    <mass value="0.12707504564350522"/>
    <inertia ixx="2.1e-05" ixy="0.0" ixz="0.0" iyy="3.7e-05" iyz="0.0" izz="2.1e-05"/>
  </inertial>
  <visual>
    <origin rpy="0 0 0" xyz="0.0 0.0505 -0.007"/>
    <geometry>
      <mesh filename="package://hokuyo_laser_robot_description/meshes/wheelv1_1.stl" scale="0.001 0.001 0.001"/>
    </geometry>
    <material name="green"/>
  </visual>
  <collision>
    <origin rpy="0 0 0" xyz="0.0 0.0505 -0.007"/>
    <geometry>
      <mesh filename="package://hokuyo_laser_robot_description/meshes/wheelv1_1.stl" scale="0.001 0.001 0.001"/>
    </geometry>
  </collision>
</link>

<link name="wheelv2_1">
  <inertial>
    <origin rpy="0 0 0" xyz="0.0 0.0 0.0"/>
    <mass value="0.12707504564350522"/>
    <inertia ixx="2.1e-05" ixy="0.0" ixz="0.0" iyy="3.7e-05" iyz="0.0" izz="2.1e-05"/>
  </inertial>
  <visual>
    <origin rpy="0 0 0" xyz="0.0 -0.0505 -0.007"/>
    <geometry>
      <mesh filename="package://hokuyo_laser_robot_description/meshes/wheelv2_1.stl" scale="0.001 0.001 0.001"/>
    </geometry>
    <material name="green"/>
  </visual>
  <collision>
    <origin  rpy="0 0 0" xyz="0.0 -0.0505 -0.007"/>
    <geometry>
      <mesh filename="package://hokuyo_laser_robot_description/meshes/wheelv2_1.stl" scale="0.001 0.001 0.001"/>
    </geometry>
  </collision>
</link>

<link name="caster1_1">
  <inertial>
    <origin rpy="0 0 0" xyz="0.047 1.0470961914283186e-18 -0.006130208333333334"/>
    <mass value="0.016646514073208912"/>
    <inertia ixx="0.0" ixy="0.0" ixz="0.0" iyy="0.0" iyz="0.0" izz="0.0"/>
  </inertial>
  <visual>
    <origin rpy="0 0 0" xyz="-0.047 0.0 7.25e-3"/>
    <geometry>
      <mesh filename="package://hokuyo_laser_robot_description/meshes/caster1_1.stl" scale="0.001 0.001 0.001"/>
    </geometry>
    <material name="silver"/>
  </visual>
  <collision>
    <origin rpy="0 0 0" xyz="-0.047 0.0 7.25e-3"/>     
    <geometry>
      <mesh filename="package://hokuyo_laser_robot_description/meshes/caster1_1.stl" scale="0.001 0.001 0.001"/>
   </geometry>
  </collision>
</link>

<link name="caster1_2">
  <inertial>
    <origin rpy="0 0 0" xyz="-0.047 1.0470961914283186e-18 -0.006130208333333334"/>
    <mass value="0.016646514073208912"/>
    <inertia ixx="0.0" ixy="0.0" ixz="0.0" iyy="0.0" iyz="0.0" izz="0.0"/>
  </inertial>
  <visual>
    <origin rpy="0 0 0" xyz="0.047 0.0 7.25e-3"/>
    <geometry>
      <mesh filename="package://hokuyo_laser_robot_description/meshes/caster1_2.stl" scale="0.001 0.001 0.001"/>
    </geometry>
    <material name="silver"/>
  </visual>
  <collision>
    <origin rpy="0 0 0" xyz="0.047 0.0 7.25e-3"/>
    <geometry>
      <mesh filename="package://hokuyo_laser_robot_description/meshes/caster1_2.stl" scale="0.001 0.001 0.001"/>
   </geometry>
  </collision>
</link>

<link name="Scanning_LiDAR_v1_1">
  <inertial>
    <!--origin rpy="0 0 0" xyz="0.0004962013390556115 2.772833039489292e-11 0.09116247912672887"/-->
    <origin rpy="0 0 0" xyz="0.0007 5.772833039489292e-11 -0.120"/>
    <mass value="0.20618724895536297"/>
    <inertia ixx="3.9e-05" ixy="0.0" ixz="-2e-06" iyy="3.9e-05" iyz="0.0" izz="6.6e-05"/>
  </inertial>
  <visual>
    <origin rpy="0 0 0" xyz="0.0 0.0 -0.115"/>
    <geometry>
      <mesh filename="package://hokuyo_laser_robot_description/meshes/Scanning_LiDAR_v1_1.stl" scale="0.001 0.001 0.001"/>
    </geometry>
    <material name="red"/>
  </visual>
  <collision>
     <origin rpy="0 0 0" xyz="0.0 0.0 -0.115"/>
   <geometry>
      <mesh filename="package://hokuyo_laser_robot_description/meshes/Scanning_LiDAR_v1_1.stl" scale="0.001 0.001 0.001"/>
      </geometry>
  </collision>
</link>

<link name="camera_link">
    <collision>
      <origin xyz="0 0 0" rpy="0 0 0"/>
      <geometry>
    <box size="0.010 0.010 0.010"/>
      </geometry>
    </collision>

    <visual>
      <origin xyz="0 0 0" rpy="0 0 0"/>
      <geometry>
       <box size="0.010 0.010 0.010"/>
      </geometry>
      <material name="green"/>
    </visual>

    <inertial>
      <mass value="1e-5" />
      <origin xyz="0 0 0" rpy="0 0 0"/>
      <inertia ixx="1e-6" ixy="0" ixz="0" iyy="1e-6" iyz="0" izz="1e-6" />
    </inertial>
  </link>

<link name="motorv1_1">
  <inertial>
    <origin rpy="0 0 0" xyz="2.6844399149895193e-05 0.006886854807477125 0.005517296211487611"/>
    <mass value="0.020522858123399677"/>
    <inertia ixx="2e-06" ixy="0.0" ixz="0.0" iyy="0.0" iyz="0.0" izz="2e-06"/>
  </inertial>
  <visual>
    <origin rpy="0 0 0" xyz="0.0 0.023 -0.007"/>
    <geometry>
      <mesh filename="package://hokuyo_laser_robot_description/meshes/motorv1_1.stl" scale="0.001 0.001 0.001"/>
    </geometry>
    <material name="orange"/>
  </visual>
  <collision>
  <origin rpy="0 0 0" xyz="0.0 0.023 -0.007"/>
    <geometry>
      <mesh filename="package://hokuyo_laser_robot_description/meshes/motorv1_1.stl" scale="0.001 0.001 0.001"/>
    </geometry>
  </collision>
</link>

<link name="motorv2_1">
  <inertial>
    <origin rpy="0 0 0" xyz="-2.6844399149895193e-05 -0.006886854807477125 0.005517296211487611"/>
    <mass value="0.020522858123399677"/>
    <inertia ixx="2e-06" ixy="0.0" ixz="0.0" iyy="0.0" iyz="0.0" izz="2e-06"/>
  </inertial>
  <visual>
  
   <origin rpy="0 0 0" xyz="0.0 -0.023 -0.007"/>
    <geometry>
      <mesh filename="package://hokuyo_laser_robot_description/meshes/motorv2_1.stl" scale="0.001 0.001 0.001"/>
    </geometry>
    <material name="orange"/>
  </visual>
  <collision> 
  <origin  rpy="0 0 0" xyz="0.0 -0.023 -0.007"/>
    <geometry>
      <mesh filename="package://hokuyo_laser_robot_description/meshes/motorv2_1.stl" scale="0.001 0.001 0.001"/>
    </geometry>
  </collision>
</link>


<joint name="right_wheel_joint" type="continuous">
  <origin rpy="0 0 0" xyz="0.0 -0.05 0.00562"/>
  <parent link="base_link"/>
  <child link="wheelv1_1"/>
  <axis xyz="0 1 0" />
</joint>



<joint name="left_wheel_joint" type="continuous">
  <origin rpy="0 0 0" xyz="0.0 0.05 0.00562"/>
  <parent link="base_link"/>
  <child link="wheelv2_1"/>
  <axis xyz="0 1 0" />
</joint>

<joint name="Rigid7" type="fixed">
  <origin rpy="0 0 0" xyz="0.047 0.0 -7.25e-3"/>
  <parent link="base_link"/>
  <child link="caster1_1"/>
</joint>

<joint name="Rigid8" type="fixed">
  <origin rpy="0 0 0" xyz="-0.047 0.0 -7.25e-3"/>
  <parent link="base_link"/>
  <child link="caster1_2"/>
</joint>

<joint name="Rigid6" type="fixed">
  <origin rpy="0 0 0" xyz="0.0 0.0 0.115"/>
  <parent link="base_link"/>
  <child link="Scanning_LiDAR_v1_1"/>
</joint>

<joint name="camera_joint" type="fixed">
    <axis xyz="0 1 0" />

    <origin xyz="0.055 0 0.049" rpy="0 0 0"/>
    <parent link="base_link"/>
    <child link="camera_link"/>
  </joint>

<joint name="Rigid2" type="fixed">
  <origin rpy="0 0 0" xyz="0.0 -0.023 0.007"/>
  <parent link="base_link"/>
  <child link="motorv1_1"/>
</joint>

<joint name="Rigid3" type="fixed">
  
  <origin rpy="0 0 0" xyz="0.0 0.023 0.007"/>
  <parent link="base_link"/>
  <child link="motorv2_1"/>
</joint>



</robot>
